#VRML_SIM R2019a utf8
WorldInfo {
}
Viewpoint {
  orientation -0.5017278143163673 0.8529397180029383 0.144093850647379 0.6042463268785578
  position 1.140800801550548 0.6239898003378433 1.5690357995324158
}
TexturedBackground {
}
TexturedBackgroundLight {
}
Floor {
}
Solid {
  translation 0 0.12999999999999998 0
  children [
    Shape {
      appearance PBRAppearance {
        baseColor 0.4470588235294118 0.6235294117647059 0.8117647058823529
      }
      geometry Box {
        size 1 0.01 0.1
      }
    }
    HingeJoint {
      jointParameters HingeJointParameters {
        anchor 0.5 0 0
      }
      endPoint Solid {
        translation 0.6 0 0
        children [
          Shape {
            appearance PBRAppearance {
              baseColor 0.8 0 0
            }
            geometry Box {
              size 0.2 0.01 0.1
            }
          }
        ]
      }
    }
  ]
}
